<?xml version="1.0" encoding="utf-8"?>
<!-- This URDF was automatically created by SolidWorks to URDF Exporter! Originally created by Stephen Brawner (brawner@gmail.com) 
     Commit Version: 1.6.0-4-g7f85cfe  Build Version: 1.6.7995.38578
     For more information, please see http://wiki.ros.org/sw_urdf_exporter -->
<robot
  name="ignition_robot" xmlns:xacro="http://www.ros.org/wiki/xacro">
  <link
    name="base_link">
    <inertial>
      <origin
        xyz="1.82408478044405E-07 3.5171601447271E-06 0.00902025307249439"
        rpy="0 0 0" />
      <mass
        value="0.600112766264777" />
      <inertia
        ixx="0.00142271929258326"
        ixy="-1.84401120990181E-08"
        ixz="2.64639323251921E-09"
        iyy="0.00138396714319135"
        iyz="-9.69141190387362E-08"
        izz="0.00267251954660063" />
    </inertial>
    <visual>
      <origin
        xyz="0 0 0"
        rpy="0 0 0" />
      <geometry>
        <mesh
          filename="package://ignition_robot/meshes/base_link.STL" />
      </geometry>
      <material
        name="">
        <color
          rgba="0.894117647058823 0.913725490196078 0.929411764705882 1" />
      </material>
    </visual>
    <collision>
      <origin
        xyz="0 0 0"
        rpy="0 0 0" />
      <geometry>
        <mesh
          filename="package://ignition_robot/meshes/base_link.STL" />
      </geometry>
    </collision>
  </link>
  <link
    name="j1_Link">
    <inertial>
      <origin
        xyz="-2.25326300358347E-05 -0.00342275072503672 0.0379899100798883"
        rpy="0 0 0" />
      <mass
        value="0.178697895356697" />
      <inertia
        ixx="7.96290461233834E-05"
        ixy="-2.55980621480004E-08"
        ixz="2.94304187104021E-08"
        iyy="9.47363858187762E-05"
        iyz="-6.46778588079666E-06"
        izz="7.81564431390067E-05" />
    </inertial>
    <visual>
      <origin
        xyz="0 0 0"
        rpy="0 0 0" />
      <geometry>
        <mesh
          filename="package://ignition_robot/meshes/j1_Link.STL" />
      </geometry>
      <material
        name="">
        <color
          rgba="0.792156862745098 0.819607843137255 0.933333333333333 1" />
      </material>
    </visual>
    <collision>
      <origin
        xyz="0 0 0"
        rpy="0 0 0" />
      <geometry>
        <mesh
          filename="package://ignition_robot/meshes/j1_Link.STL" />
      </geometry>
    </collision>
  </link>
  <joint
    name="joint1"
    type="continuous">
    <origin
      xyz="0 0 0.06325"
      rpy="0 0 0" />
    <parent
      link="base_link" />
    <child
      link="j1_Link" />
    <axis
      xyz="0 0 1" />
    <limit
      lower="-6.28"
      upper="6.28"
      effort="100"
      velocity="2.0" />
  </joint>
  <link
    name="j2_Link">
    <inertial>
      <origin
        xyz="-0.032745268672496 0.0013536847083217 0.145506466953313"
        rpy="0 0 0" />
      <mass
        value="0.211213463622213" />
      <inertia
        ixx="0.000205676730407739"
        ixy="-1.90332013944453E-08"
        ixz="5.15467557655185E-06"
        iyy="0.000200708429392805"
        iyz="5.59683345691876E-08"
        izz="9.53384585245136E-05" />
    </inertial>
    <visual>
      <origin
        xyz="0 0 0"
        rpy="0 0 0" />
      <geometry>
        <mesh
          filename="package://ignition_robot/meshes/j2_Link.STL" />
      </geometry>
      <material
        name="">
        <color
          rgba="0.792156862745098 0.819607843137255 0.933333333333333 1" />
      </material>
    </visual>
    <collision>
      <origin
        xyz="0 0 0"
        rpy="0 0 0" />
      <geometry>
        <mesh
          filename="package://ignition_robot/meshes/j2_Link.STL" />
      </geometry>
    </collision>
  </link>
  <joint
    name="joint2"
    type="revolute">
    <origin
      xyz="0.00131462848711156 0.0307218850468486 0.0419000000004602"
      rpy="0 0 1.5707963267949" />
    <parent
      link="j1_Link" />
    <child
      link="j2_Link" />
    <axis
      xyz="1 0 0" />
    <limit
      lower="-1.5708"
      upper="1.5708"
      effort="100"
      velocity="2.0" />
  </joint>
  <link
    name="j3_Link">
    <inertial>
      <origin
        xyz="-2.31977252626164E-05 0.00291620685617054 0.0400293534082172"
        rpy="0 0 0" />
      <mass
        value="0.179709253020695" />
      <inertia
        ixx="8.1199514155749E-05"
        ixy="3.02662559214377E-08"
        ixz="1.22308541621717E-08"
        iyy="9.67926159536108E-05"
        iyz="6.76084403304123E-06"
        izz="7.869771879242E-05" />
    </inertial>
    <visual>
      <origin
        xyz="0 0 0"
        rpy="0 0 0" />
      <geometry>
        <mesh
          filename="package://ignition_robot/meshes/j3_Link.STL" />
      </geometry>
      <material
        name="">
        <color
          rgba="0.792156862745098 0.819607843137255 0.933333333333333 1" />
      </material>
    </visual>
    <collision>
      <origin
        xyz="0 0 0"
        rpy="0 0 0" />
      <geometry>
        <mesh
          filename="package://ignition_robot/meshes/j3_Link.STL" />
      </geometry>
    </collision>
  </link>
  <joint
    name="joint3"
    type="continuous">
    <origin
      xyz="-0.041872 0.0013146 0.1858"
      rpy="0 0 -1.5708" />
    <parent
      link="j2_Link" />
    <child
      link="j3_Link" />
    <axis
      xyz="0 0 -1" />
    <limit
      lower="-6.28"
      upper="6.28"
      effort="100"
      velocity="2.0" />
  </joint>
  <link
    name="j4_Link">
    <inertial>
      <origin
        xyz="0.0348796386523761 0.0675512627754756 2.81388455863896E-06"
        rpy="0 0 0" />
      <mass
        value="0.177550051277307" />
      <inertia
        ixx="8.77595407624009E-05"
        ixy="-4.80729587152777E-06"
        ixz="9.65461937237769E-08"
        iyy="8.41215441102613E-05"
        iyz="-5.5072218561839E-09"
        izz="8.32581338510293E-05" />
    </inertial>
    <visual>
      <origin
        xyz="0 0 0"
        rpy="0 0 0" />
      <geometry>
        <mesh
          filename="package://ignition_robot/meshes/j4_Link.STL" />
      </geometry>
      <material
        name="">
        <color
          rgba="0.792156862745098 0.819607843137255 0.933333333333333 1" />
      </material>
    </visual>
    <collision>
      <origin
        xyz="0 0 0"
        rpy="0 0 0" />
      <geometry>
        <mesh
          filename="package://ignition_robot/meshes/j4_Link.STL" />
      </geometry>
    </collision>
  </link>
  <joint
    name="joint4"
    type="revolute">
    <origin
      xyz="0 -0.03125 0.0442"
      rpy="1.5708 0 1.5708" />
    <parent
      link="j3_Link" />
    <child
      link="j4_Link" />
    <axis
      xyz="-1 0 0" />
    <limit
      lower="-1.5708"
      upper="1.5708"
      effort="100"
      velocity="2.0" />
  </joint>
  <link
    name="j5_Link">
    <inertial>
      <origin
        xyz="2.17145196302129E-06 0.00184970906097347 0.0451788113372391"
        rpy="0 0 0" />
      <mass
        value="0.157116859298686" />
      <inertia
        ixx="6.61602205931627E-05"
        ixy="7.5298842820805E-10"
        ixz="-2.69360064954105E-08"
        iyy="5.66350767382595E-05"
        iyz="6.07294412166664E-07"
        izz="6.2338022592871E-05" />
    </inertial>
    <visual>
      <origin
        xyz="0 0 0"
        rpy="0 0 0" />
      <geometry>
        <mesh
          filename="package://ignition_robot/meshes/j5_Link.STL" />
      </geometry>
      <material
        name="">
        <color
          rgba="0.792156862745098 0.819607843137255 0.933333333333333 1" />
      </material>
    </visual>
    <collision>
      <origin
        xyz="0 0 0"
        rpy="0 0 0" />
      <geometry>
        <mesh
          filename="package://ignition_robot/meshes/j5_Link.STL" />
      </geometry>
    </collision>
  </link>
  <joint
    name="joint5"
    type="continuous">
    <origin
      xyz="0.0424 0.09375 0"
      rpy="-1.5708 0 0" />
    <parent
      link="j4_Link" />
    <child
      link="j5_Link" />
    <axis
      xyz="0 0 -1" />
    <limit
      lower="-6.28"
      upper="6.28"
      effort="100"
      velocity="2.0" />
  </joint>
  <link
    name="j6_Link">
    <inertial>
      <origin
        xyz="-0.00117965042886864 -0.000196659499277052 -0.0364705248322783"
        rpy="0 0 0" />
      <mass
        value="0.110800280869944" />
      <inertia
        ixx="4.27157351025654E-05"
        ixy="-1.80740498250332E-08"
        ixz="6.05086778605281E-08"
        iyy="3.13351266513017E-05"
        iyz="8.86134492632792E-08"
        izz="3.15911686246525E-05" />
    </inertial>
    <visual>
      <origin
        xyz="0 0 0"
        rpy="0 0 0" />
      <geometry>
        <mesh
          filename="package://ignition_robot/meshes/j6_Link.STL" />
      </geometry>
      <material
        name="">
        <color
          rgba="0.792156862745098 0.819607843137255 0.933333333333333 1" />
      </material>
    </visual>
    <collision>
      <origin
        xyz="0 0 0"
        rpy="0 0 0" />
      <geometry>
        <mesh
          filename="package://ignition_robot/meshes/j6_Link.STL" />
      </geometry>
    </collision>
  </link>
  <joint
    name="joint6"
    type="revolute">
    <origin
      xyz="0 -0.0365000000003447 0.118365606252056"
      rpy="1.5707963267949 0 0" />
    <parent
      link="j5_Link" />
    <child
      link="j6_Link" />
    <axis
      xyz="0 0 1" />
    <limit
      lower="-0.2618"
      upper="0.48869"
      effort="100"
      velocity="2.0" />
  </joint>
  <link
    name="j7_Link">
    <inertial>
      <origin
        xyz="0.0294522859031681 0.0261818743734258 -6.36023244321438E-07"
        rpy="0 0 0" />
      <mass
        value="0.0322852554420248" />
      <inertia
        ixx="8.60304158020682E-06"
        ixy="2.19860593205127E-07"
        ixz="1.55863612963084E-11"
        iyy="5.20603754670291E-06"
        iyz="-1.90910700619655E-10"
        izz="7.94640614714226E-06" />
    </inertial>
    <visual>
      <origin
        xyz="0 0 0"
        rpy="0 0 0" />
      <geometry>
        <mesh
          filename="package://ignition_robot/meshes/j7_Link.STL" />
      </geometry>
      <material
        name="">
        <color
          rgba="0.792156862745098 0.819607843137255 0.933333333333333 1" />
      </material>
    </visual>
    <collision>
      <origin
        xyz="0 0 0"
        rpy="0 0 0" />
      <geometry>
        <mesh
          filename="package://ignition_robot/meshes/j7_Link.STL" />
      </geometry>
    </collision>
  </link>
  <joint
    name="joint7"
    type="revolute">
    <origin
      xyz="-0.0335 0 -0.0364999999999997"
      rpy="0 0 0" />
    <parent
      link="j6_Link" />
    <child
      link="j7_Link" />
    <axis
      xyz="-1 0 0" />
    <limit
      lower="-1.5708"
      upper="1.5708"
      effort="100"
      velocity="2.0" />
  </joint>

  <!-- Ignition Gazebo Plugins -->
  <gazebo>
    <plugin filename="ignition-gazebo-joint-state-publisher-system"
            name="ignition::gazebo::systems::JointStatePublisher">
    </plugin>
    
    <plugin filename="ignition-gazebo-joint-position-controller-system"
            name="ignition::gazebo::systems::JointPositionController">
      <joint_name>joint1</joint_name>
      <topic>/joint1/cmd_pos</topic>
      <p_gain>5</p_gain>
      <i_gain>0.1</i_gain>
      <d_gain>0.1</d_gain>
    </plugin>
    
    <plugin filename="ignition-gazebo-joint-position-controller-system"
            name="ignition::gazebo::systems::JointPositionController">
      <joint_name>joint2</joint_name>
      <topic>/joint2/cmd_pos</topic>
      <p_gain>5</p_gain>
      <i_gain>0.1</i_gain>
      <d_gain>0.1</d_gain>
    </plugin>
    
    <plugin filename="ignition-gazebo-joint-position-controller-system"
            name="ignition::gazebo::systems::JointPositionController">
      <joint_name>joint3</joint_name>
      <topic>/joint3/cmd_pos</topic>
      <p_gain>5</p_gain>
      <i_gain>0.1</i_gain>
      <d_gain>0.1</d_gain>
    </plugin>
    
    <plugin filename="ignition-gazebo-joint-position-controller-system"
            name="ignition::gazebo::systems::JointPositionController">
      <joint_name>joint4</joint_name>
      <topic>/joint4/cmd_pos</topic>
      <p_gain>5</p_gain>
      <i_gain>0.1</i_gain>
      <d_gain>0.1</d_gain>
    </plugin>
    
    <plugin filename="ignition-gazebo-joint-position-controller-system"
            name="ignition::gazebo::systems::JointPositionController">
      <joint_name>joint5</joint_name>
      <topic>/joint5/cmd_pos</topic>
      <p_gain>5</p_gain>
      <i_gain>0.1</i_gain>
      <d_gain>0.1</d_gain>
    </plugin>
    
    <plugin filename="ignition-gazebo-joint-position-controller-system"
            name="ignition::gazebo::systems::JointPositionController">
      <joint_name>joint6</joint_name>
      <topic>/joint6/cmd_pos</topic>
      <p_gain>5</p_gain>
      <i_gain>0.1</i_gain>
      <d_gain>0.1</d_gain>
    </plugin>
    
    <plugin filename="ignition-gazebo-joint-position-controller-system"
            name="ignition::gazebo::systems::JointPositionController">
      <joint_name>joint7</joint_name>
      <topic>/joint7/cmd_pos</topic>
      <p_gain>5</p_gain>
      <i_gain>0.1</i_gain>
      <d_gain>0.1</d_gain>
    </plugin>
  </gazebo>

</robot>